Workbook

Sheet Cover
A1: CALCULATION WORKBOOK - ANCHORAGE AND LAP LENGTHS
A2: PJR-2026-003_WAREHOUSE (STEAM BOILER)
A4: Workbook number | B4: WH-STR-WB-001
A5: Project | B5: PJR-2026-003 WAREHOUSE (STEAM BOILER)
A6: Client | B6: Mr. XXX
A7: Stage | B7: FOR APPROVAL
A8: Revision | B8: R00
A9: Issue date | B9: 13-OCT-2026
A10: Design basis status | B10: DRAFT
A11: Prepared by | B11: P.LIHENG
A12: Checked by
A13: Approved by
A15: STATUS | B15: =IF(COUNTIF(Checks!G5:G12,"FAIL")>0,"CHECKS FAILING - DO NOT USE",IF(COUNTIF(Checks!G5:G12,"PASS")=0,"UNVERIFIED - inputs differ from the checked baseline",IF(B12="","CROSS-CHECKED - NOT ENGINEER-REVIEWED","REVIEWED BY "&B12))) -> CROSS-CHECKED - NOT ENGINEER-REVIEWED
A16: Stamp | B16: =IF(B10="APPROVED","","DRAFT - NOT FOR ISSUE") -> DRAFT - NOT FOR ISSUE
A18: Colour legend
A19: Blue text on yellow | B19: Input - the only cells to edit (Inputs sheet, plus Checked/Approved by above)
A20: Black text | B20: Formula or fixed label - do not overwrite
A22: Sheets
A23: Inputs | B23: all typed values with unit, source, status
A24: Calc | B24: formulas only
A25: Outputs | B25: results and reconciliation with SD-004
A26: Checks | B26: hand-calculated tests
A27: Log | B27: change log
A29: Limits: one check only (basic anchorage/lap length). Not a complete design. Status is never 'validated' without a named reviewer.

Sheet Inputs
A1: INPUTS - EN 1992-1-1 anchorage and lap lengths
A2: Blue cells on yellow are the only cells to edit. Every value has a unit, source and status.
A3: Symbol | B3: Description | C3: Value | D3: Unit | E3: Source | F3: Status
A4: Material inputs
A5: concrete class | B5: Concrete strength class | C5: C30/37 | D5: - | E5: design basis M-CONC-PILE (SD-004 section A) | F5: confirmed
A6: fyk | B6: Characteristic yield strength of reinforcement | C6: 390 | D6: MPa | E6: design basis M-REBAR (SD-004 section A) | F6: confirmed
A7: fctk,0.05 override | B7: Leave BLANK to use EN 1992-1-1 Table 3.1 (table below) | D7: MPa | E7: User option | F7: -
A8: fctk,0.05 drawing basis | B8: Value implied by SD-004 (fbd = 3.04 MPa): 0.7 x fctm, fctm = 2.9 MPa | C8: 2.03 | D8: MPa | E8: WH-STR-SD-004 section C note; EN 1992-1-1 Table 3.1 (fctm) | F8: confirmed
A9: Partial factors and coefficients (CEN recommended values, no National Annex)
A10: gamma_c | B10: Partial factor, concrete | C10: 1.5 | D10: - | E10: EN 1992-1-1 Table 2.1N (CEN recommended) | F10: confirmed
A11: gamma_s | B11: Partial factor, reinforcing steel | C11: 1.15 | D11: - | E11: EN 1992-1-1 Table 2.1N (CEN recommended) | F11: confirmed
A12: alpha_ct | B12: Long-term effects coefficient on tensile strength | C12: 1 | D12: - | E12: EN 1992-1-1 3.1.6(2)P (CEN recommended) | F12: confirmed
A13: alpha_6 | B13: Lap factor, 50 % of bars lapped in the section | C13: 1.5 | D13: - | E13: EN 1992-1-1 Table 8.3 | F13: confirmed
A15: Expression constants (EN 1992-1-1 eq. 8.2 and 3.1)
A16: 2.25 | B16: Coefficient in fbd = 2.25 x eta1 x eta2 x fctd | C16: 2.25 | D16: - | E16: EN 1992-1-1 eq. 8.2 | F16: confirmed
A17: eta1 good | B17: Bond condition coefficient, good | C17: 1 | D17: - | E17: EN 1992-1-1 8.4.2(2) | F17: confirmed
A18: eta1 poor | B18: Bond condition coefficient, poor | C18: 0.7 | D18: - | E18: EN 1992-1-1 8.4.2(2) | F18: confirmed
A19: eta2 limit | B19: Bar diameter up to which eta2 = 1.0 | C19: 32 | D19: mm | E19: EN 1992-1-1 8.4.2(2) | F19: confirmed
A20: eta2 a | B20: eta2 = (a - phi)/b for phi above the limit: a | C20: 132 | D20: mm | E20: EN 1992-1-1 8.4.2(2) | F20: confirmed
A21: eta2 b | B21: eta2 = (a - phi)/b: b | C21: 100 | D21: - | E21: EN 1992-1-1 8.4.2(2) | F21: confirmed
A23: EN 1992-1-1 Table 3.1: fctk,0.05 by class (extend only with values read from the standard)
A24: C25/30 | B24: fctk,0.05 | C24: 1.8 | D24: MPa | E24: EN 1992-1-1 Table 3.1 | F24: confirmed
A25: C30/37 | B25: fctk,0.05 | C25: 2 | D25: MPa | E25: EN 1992-1-1 Table 3.1 | F25: confirmed
A26: C35/45 | B26: fctk,0.05 | C26: 2.2 | D26: MPa | E26: EN 1992-1-1 Table 3.1 | F26: confirmed
A27: C40/50 | B27: fctk,0.05 | C27: 2.5 | D27: MPa | E27: EN 1992-1-1 Table 3.1 | F27: confirmed
A29: Bar diameters (up to 8; leave unused rows blank)
A30: bar 1 | B30: Bar diameter | C30: 10 | D30: mm | E30: Project reinforcement schedule | F30: confirmed
A31: bar 2 | B31: Bar diameter | C31: 12 | D31: mm | E31: Project reinforcement schedule | F31: confirmed
A32: bar 3 | B32: Bar diameter | C32: 16 | D32: mm | E32: Project reinforcement schedule | F32: confirmed
A33: bar 4 | B33: Bar diameter | C33: 20 | D33: mm | E33: Project reinforcement schedule | F33: confirmed
A34: bar 5 | B34: Bar diameter | C34: 25 | D34: mm | E34: Project reinforcement schedule | F34: confirmed
A35: bar 6 | B35: Bar diameter | D35: mm
A36: bar 7 | B36: Bar diameter | D36: mm
A37: bar 8 | B37: Bar diameter | D37: mm
A39: Drawing values for reconciliation: WH-STR-SD-004 section C (leave blank to skip)
A40: Bar | C40: lbd good (mm) | D40: lbd poor (mm) | E40: lap l0 good (mm) | F40: mandrel (mm)
A41: bar 1 | C41: 280 | D41: 400 | E41: 420 | F41: 40
A42: bar 2 | C42: 335 | D42: 480 | E42: 505 | F42: 48
A43: bar 3 | C43: 445 | D43: 640 | E43: 670 | F43: 64
A44: bar 4 | C44: 560 | D44: 800 | E44: 840 | F44: 140
...

Sheet Calc
A1: CALC - formulas only (no typed numbers)
A2: Clause references in the last column. Stresses MPa, lengths mm.
A3: Quantity | C3: Value | D3: Unit | E3: Expression / clause
A4: fctk,0.05 used | C4: =IF(Inputs!$C$7<>"",Inputs!$C$7,INDEX(Inputs!$C$24:$C$27,MATCH(Inputs!$C$5,Inputs!$A$24:$A$27,0))) -> 2 | D4: MPa | E4: Table 3.1, or override
A5: fctd | C5: =Inputs!$C$12*C4/Inputs!$C$10 -> 1.3333333 | D5: MPa | E5: EN 1992-1-1 eq. 3.16: alpha_ct x fctk,0.05 / gamma_c
A6: fyd = sigma_sd | C6: =Inputs!$C$6/Inputs!$C$11 -> 339.13043 | D6: MPa | E6: fyk / gamma_s
A7: fctd, drawing basis | C7: =Inputs!$C$12*Inputs!$C$8/Inputs!$C$10 -> 1.3533333 | D7: MPa | E7: as above with fctk,0.05 = drawing basis
A8: eq. 8.2: fbd = 2.25 x eta1 x eta2 x fctd; eq. 8.3: lb,rqd = (phi/4) x sigma_sd / fbd; lap = alpha_6 x lb,rqd
A9: Bar phi (mm) | B9: eta2 | C9: fbd good (MPa) | D9: fbd poor (MPa) | E9: lb,rqd good (mm) | F9: lb,rqd poor (mm) | G9: lap l0 good (mm) | H9: lb good, dwg basis | I9: lb poor, dwg basis | J9: lap good, dwg basis
A10: =IF(Inputs!$C$30="","",Inputs!$C$30) -> 10 | B10: =IF($A10="","",IF($A10<=Inputs!$C$19,1,(Inputs!$C$20-$A10)/Inputs!$C$21)) -> 1 | C10: =IF($A10="","",Inputs!$C$16*Inputs!$C$17*B10*$C$5) -> 3 | D10: =IF($A10="","",Inputs!$C$16*Inputs!$C$18*B10*$C$5) -> 2.1 | E10: =IF($A10="","",$A10/4*$C$6/C10) -> 282.6087 | F10: =IF($A10="","",$A10/4*$C$6/D10) -> 403.72671 | G10: =IF($A10="","",Inputs!$C$13*E10) -> 423.91304 | H10: =IF($A10="","",$A10/4*$C$6/(Inputs!$C$16*Inputs!$C$17*B10*$C$7)) -> 278.43221 | I10: =IF($A10="","",$A10/4*$C$6/(Inputs!$C$16*Inputs!$C$18*B10*$C$7)) -> 397.7603 | J10: =IF($A10="","",Inputs!$C$13*H10) -> 417.64832
A11: =IF(Inputs!$C$31="","",Inputs!$C$31) -> 12 | B11: =IF($A11="","",IF($A11<=Inputs!$C$19,1,(Inputs!$C$20-$A11)/Inputs!$C$21)) -> 1 | C11: =IF($A11="","",Inputs!$C$16*Inputs!$C$17*B11*$C$5) -> 3 | D11: =IF($A11="","",Inputs!$C$16*Inputs!$C$18*B11*$C$5) -> 2.1 | E11: =IF($A11="","",$A11/4*$C$6/C11) -> 339.13043 | F11: =IF($A11="","",$A11/4*$C$6/D11) -> 484.47205 | G11: =IF($A11="","",Inputs!$C$13*E11) -> 508.69565 | H11: =IF($A11="","",$A11/4*$C$6/(Inputs!$C$16*Inputs!$C$17*B11*$C$7)) -> 334.11865 | I11: =IF($A11="","",$A11/4*$C$6/(Inputs!$C$16*Inputs!$C$18*B11*$C$7)) -> 477.31236 | J11: =IF($A11="","",Inputs!$C$13*H11) -> 501.17798
A12: =IF(Inputs!$C$32="","",Inputs!$C$32) -> 16 | B12: =IF($A12="","",IF($A12<=Inputs!$C$19,1,(Inputs!$C$20-$A12)/Inputs!$C$21)) -> 1 | C12: =IF($A12="","",Inputs!$C$16*Inputs!$C$17*B12*$C$5) -> 3 | D12: =IF($A12="","",Inputs!$C$16*Inputs!$C$18*B12*$C$5) -> 2.1 | E12: =IF($A12="","",$A12/4*$C$6/C12) -> 452.17391 | F12: =IF($A12="","",$A12/4*$C$6/D12) -> 645.96273 | G12: =IF($A12="","",Inputs!$C$13*E12) -> 678.26087 | H12: =IF($A12="","",$A12/4*$C$6/(Inputs!$C$16*Inputs!$C$17*B12*$C$7)) -> 445.49154 | I12: =IF($A12="","",$A12/4*$C$6/(Inputs!$C$16*Inputs!$C$18*B12*$C$7)) -> 636.41649 | J12: =IF($A12="","",Inputs!$C$13*H12) -> 668.23731
A13: =IF(Inputs!$C$33="","",Inputs!$C$33) -> 20 | B13: =IF($A13="","",IF($A13<=Inputs!$C$19,1,(Inputs!$C$20-$A13)/Inputs!$C$21)) -> 1 | C13: =IF($A13="","",Inputs!$C$16*Inputs!$C$17*B13*$C$5) -> 3 | D13: =IF($A13="","",Inputs!$C$16*Inputs!$C$18*B13*$C$5) -> 2.1 | E13: =IF($A13="","",$A13/4*$C$6/C13) -> 565.21739 | F13: =IF($A13="","",$A13/4*$C$6/D13) -> 807.45342 | G13: =IF($A13="","",Inputs!$C$13*E13) -> 847.82609 | H13: =IF($A13="","",$A13/4*$C$6/(Inputs!$C$16*Inputs!$C$17*B13*$C$7)) -> 556.86442 | I13: =IF($A13="","",$A13/4*$C$6/(Inputs!$C$16*Inputs!$C$18*B13*$C$7)) -> 795.52061 | J13: =IF($A13="","",Inputs!$C$13*H13) -> 835.29664
A14: =IF(Inputs!$C$34="","",Inputs!$C$34) -> 25 | B14: =IF($A14="","",IF($A14<=Inputs!$C$19,1,(Inputs!$C$20-$A14)/Inputs!$C$21)) -> 1 | C14: =IF($A14="","",Inputs!$C$16*Inputs!$C$17*B14*$C$5) -> 3 | D14: =IF($A14="","",Inputs!$C$16*Inputs!$C$18*B14*$C$5) -> 2.1 | E14: =IF($A14="","",$A14/4*$C$6/C14) -> 706.52174 | F14: =IF($A14="","",$A14/4*$C$6/D14) -> 1009.3168 | G14: =IF($A14="","",Inputs!$C$13*E14) -> 1059.7826 | H14: =IF($A14="","",$A14/4*$C$6/(Inputs!$C$16*Inputs!$C$17*B14*$C$7)) -> 696.08053 | I14: =IF($A14="","",$A14/4*$C$6/(Inputs!$C$16*Inputs!$C$18*B14*$C$7)) -> 994.40076 | J14: =IF($A14="","",Inputs!$C$13*H14) -> 1044.1208
A15: =IF(Inputs!$C$35="","",Inputs!$C$35) | B15: =IF($A15="","",IF($A15<=Inputs!$C$19,1,(Inputs!$C$20-$A15)/Inputs!$C$21)) | C15: =IF($A15="","",Inputs!$C$16*Inputs!$C$17*B15*$C$5) | D15: =IF($A15="","",Inputs!$C$16*Inputs!$C$18*B15*$C$5) | E15: =IF($A15="","",$A15/4*$C$6/C15) | F15: =IF($A15="","",$A15/4*$C$6/D15) | G15: =IF($A15="","",Inputs!$C$13*E15) | H15: =IF($A15="","",$A15/4*$C$6/(Inputs!$C$16*Inputs!$C$17*B15*$C$7)) | I15: =IF($A15="","",$A15/4*$C$6/(Inputs!$C$16*Inputs!$C$18*B15*$C$7)) | J15: =IF($A15="","",Inputs!$C$13*H15)
A16: =IF(Inputs!$C$36="","",Inputs!$C$36) | B16: =IF($A16="","",IF($A16<=Inputs!$C$19,1,(Inputs!$C$20-$A16)/Inputs!$C$21)) | C16: =IF($A16="","",Inputs!$C$16*Inputs!$C$17*B16*$C$5) | D16: =IF($A16="","",Inputs!$C$16*Inputs!$C$18*B16*$C$5) | E16: =IF($A16="","",$A16/4*$C$6/C16) | F16: =IF($A16="","",$A16/4*$C$6/D16) | G16: =IF($A16="","",Inputs!$C$13*E16) | H16: =IF($A16="","",$A16/4*$C$6/(Inputs!$C$16*Inputs!$C$17*B16*$C$7)) | I16: =IF($A16="","",$A16/4*$C$6/(Inputs!$C$16*Inputs!$C$18*B16*$C$7)) | J16: =IF($A16="","",Inputs!$C$13*H16)
A17: =IF(Inputs!$C$37="","",Inputs!$C$37) | B17: =IF($A17="","",IF($A17<=Inputs!$C$19,1,(Inputs!$C$20-$A17)/Inputs!$C$21)) | C17: =IF($A17="","",Inputs!$C$16*Inputs!$C$17*B17*$C$5) | D17: =IF($A17="","",Inputs!$C$16*Inputs!$C$18*B17*$C$5) | E17: =IF($A17="","",$A17/4*$C$6/C17) | F17: =IF($A17="","",$A17/4*$C$6/D17) | G17: =IF($A17="","",Inputs!$C$13*E17) | H17: =IF($A17="","",$A17/4*$C$6/(Inputs!$C$16*Inputs!$C$17*B17*$C$7)) | I17: =IF($A17="","",$A17/4*$C$6/(Inputs!$C$16*Inputs!$C$18*B17*$C$7)) | J17: =IF($A17="","",Inputs!$C$13*H17)
A19: Scope: basic required length only (alpha_1 to alpha_5 = 1.0, lb,min not applied); straight bars; CEN recommended values.

Sheet Outputs
A1: OUTPUTS
A2: Results on the selected basis, and reconciliation with the drawing table on the drawing's own basis.
A4: Bar (mm) | B4: lb good (mm) | C4: lb poor (mm) | D4: lap good (mm) | E4: Dwg lbd good | F4: Dev (dwg-calc) | G4: Within tol? | H4: Dwg lbd poor | I4: Dev | J4: Within tol? | K4: Dwg lap good | L4: Dev | M4: Within tol?
A5: =Calc!A10 -> 10 | B5: =Calc!E10 -> 282.6087 | C5: =Calc!F10 -> 403.72671 | D5: =Calc!G10 -> 423.91304 | E5: =IF(Inputs!$C$41="","",Inputs!$C$41) -> 280 | F5: =IF(OR(E5="",Calc!$A10=""),"",E5-Calc!$H10) -> 1.5677875 | G5: =IF(F5="","",IF(ABS(F5)<=MAX(Inputs!$C$51,Inputs!$C$52*Calc!$H10),"YES","NO")) -> YES | H5: =IF(Inputs!$D$41="","",Inputs!$D$41) -> 400 | I5: =IF(OR(H5="",Calc!$A10=""),"",H5-Calc!$I10) -> 2.2396965 | J5: =IF(I5="","",IF(ABS(I5)<=MAX(Inputs!$C$51,Inputs!$C$52*Calc!$I10),"YES","NO")) -> YES | K5: =IF(Inputs!$E$41="","",Inputs!$E$41) -> 420 | L5: =IF(OR(K5="",Calc!$A10=""),"",K5-Calc!$J10) -> 2.3516813 | M5: =IF(L5="","",IF(ABS(L5)<=MAX(Inputs!$C$51,Inputs!$C$52*Calc!$J10),"YES","NO")) -> YES
A6: =Calc!A11 -> 12 | B6: =Calc!E11 -> 339.13043 | C6: =Calc!F11 -> 484.47205 | D6: =Calc!G11 -> 508.69565 | E6: =IF(Inputs!$C$42="","",Inputs!$C$42) -> 335 | F6: =IF(OR(E6="",Calc!$A11=""),"",E6-Calc!$H11) -> 0.88134504 | G6: =IF(F6="","",IF(ABS(F6)<=MAX(Inputs!$C$51,Inputs!$C$52*Calc!$H11),"YES","NO")) -> YES | H6: =IF(Inputs!$D$42="","",Inputs!$D$42) -> 480 | I6: =IF(OR(H6="",Calc!$A11=""),"",H6-Calc!$I11) -> 2.6876358 | J6: =IF(I6="","",IF(ABS(I6)<=MAX(Inputs!$C$51,Inputs!$C$52*Calc!$I11),"YES","NO")) -> YES | K6: =IF(Inputs!$E$42="","",Inputs!$E$42) -> 505 | L6: =IF(OR(K6="",Calc!$A11=""),"",K6-Calc!$J11) -> 3.8220176 | M6: =IF(L6="","",IF(ABS(L6)<=MAX(Inputs!$C$51,Inputs!$C$52*Calc!$J11),"YES","NO")) -> YES
A7: =Calc!A12 -> 16 | B7: =Calc!E12 -> 452.17391 | C7: =Calc!F12 -> 645.96273 | D7: =Calc!G12 -> 678.26087 | E7: =IF(Inputs!$C$43="","",Inputs!$C$43) -> 445 | F7: =IF(OR(E7="",Calc!$A12=""),"",E7-Calc!$H12) -> -0.49153994 | G7: =IF(F7="","",IF(ABS(F7)<=MAX(Inputs!$C$51,Inputs!$C$52*Calc!$H12),"YES","NO")) -> YES | H7: =IF(Inputs!$D$43="","",Inputs!$D$43) -> 640 | I7: =IF(OR(H7="",Calc!$A12=""),"",H7-Calc!$I12) -> 3.5835144 | J7: =IF(I7="","",IF(ABS(I7)<=MAX(Inputs!$C$51,Inputs!$C$52*Calc!$I12),"YES","NO")) -> YES | K7: =IF(Inputs!$E$43="","",Inputs!$E$43) -> 670 | L7: =IF(OR(K7="",Calc!$A12=""),"",K7-Calc!$J12) -> 1.7626901 | M7: =IF(L7="","",IF(ABS(L7)<=MAX(Inputs!$C$51,Inputs!$C$52*Calc!$J12),"YES","NO")) -> YES
A8: =Calc!A13 -> 20 | B8: =Calc!E13 -> 565.21739 | C8: =Calc!F13 -> 807.45342 | D8: =Calc!G13 -> 847.82609 | E8: =IF(Inputs!$C$44="","",Inputs!$C$44) -> 560 | F8: =IF(OR(E8="",Calc!$A13=""),"",E8-Calc!$H13) -> 3.1355751 | G8: =IF(F8="","",IF(ABS(F8)<=MAX(Inputs!$C$51,Inputs!$C$52*Calc!$H13),"YES","NO")) -> YES | H8: =IF(Inputs!$D$44="","",Inputs!$D$44) -> 800 | I8: =IF(OR(H8="",Calc!$A13=""),"",H8-Calc!$I13) -> 4.479393 | J8: =IF(I8="","",IF(ABS(I8)<=MAX(Inputs!$C$51,Inputs!$C$52*Calc!$I13),"YES","NO")) -> YES | K8: =IF(Inputs!$E$44="","",Inputs!$E$44) -> 840 | L8: =IF(OR(K8="",Calc!$A13=""),"",K8-Calc!$J13) -> 4.7033626 | M8: =IF(L8="","",IF(ABS(L8)<=MAX(Inputs!$C$51,Inputs!$C$52*Calc!$J13),"YES","NO")) -> YES
A9: =Calc!A14 -> 25 | B9: =Calc!E14 -> 706.52174 | C9: =Calc!F14 -> 1009.3168 | D9: =Calc!G14 -> 1059.7826 | E9: =IF(Inputs!$C$45="","",Inputs!$C$45) -> 700 | F9: =IF(OR(E9="",Calc!$A14=""),"",E9-Calc!$H14) -> 3.9194688 | G9: =IF(F9="","",IF(ABS(F9)<=MAX(Inputs!$C$51,Inputs!$C$52*Calc!$H14),"YES","NO")) -> YES | H9: =IF(Inputs!$D$45="","",Inputs!$D$45) -> 1000 | I9: =IF(OR(H9="",Calc!$A14=""),"",H9-Calc!$I14) -> 5.5992412 | J9: =IF(I9="","",IF(ABS(I9)<=MAX(Inputs!$C$51,Inputs!$C$52*Calc!$I14),"YES","NO")) -> YES | K9: =IF(Inputs!$E$45="","",Inputs!$E$45) -> 1050 | L9: =IF(OR(K9="",Calc!$A14=""),"",K9-Calc!$J14) -> 5.8792033 | M9: =IF(L9="","",IF(ABS(L9)<=MAX(Inputs!$C$51,Inputs!$C$52*Calc!$J14),"YES","NO")) -> YES
A10: =Calc!A15 | B10: =Calc!E15 | C10: =Calc!F15 | D10: =Calc!G15 | E10: =IF(Inputs!$C$46="","",Inputs!$C$46) | F10: =IF(OR(E10="",Calc!$A15=""),"",E10-Calc!$H15) | G10: =IF(F10="","",IF(ABS(F10)<=MAX(Inputs!$C$51,Inputs!$C$52*Calc!$H15),"YES","NO")) | H10: =IF(Inputs!$D$46="","",Inputs!$D$46) | I10: =IF(OR(H10="",Calc!$A15=""),"",H10-Calc!$I15) | J10: =IF(I10="","",IF(ABS(I10)<=MAX(Inputs!$C$51,Inputs!$C$52*Calc!$I15),"YES","NO")) | K10: =IF(Inputs!$E$46="","",Inputs!$E$46) | L10: =IF(OR(K10="",Calc!$A15=""),"",K10-Calc!$J15) | M10: =IF(L10="","",IF(ABS(L10)<=MAX(Inputs!$C$51,Inputs!$C$52*Calc!$J15),"YES","NO"))
A11: =Calc!A16 | B11: =Calc!E16 | C11: =Calc!F16 | D11: =Calc!G16 | E11: =IF(Inputs!$C$47="","",Inputs!$C$47) | F11: =IF(OR(E11="",Calc!$A16=""),"",E11-Calc!$H16) | G11: =IF(F11="","",IF(ABS(F11)<=MAX(Inputs!$C$51,Inputs!$C$52*Calc!$H16),"YES","NO")) | H11: =IF(Inputs!$D$47="","",Inputs!$D$47) | I11: =IF(OR(H11="",Calc!$A16=""),"",H11-Calc!$I16) | J11: =IF(I11="","",IF(ABS(I11)<=MAX(Inputs!$C$51,Inputs!$C$52*Calc!$I16),"YES","NO")) | K11: =IF(Inputs!$E$47="","",Inputs!$E$47) | L11: =IF(OR(K11="",Calc!$A16=""),"",K11-Calc!$J16) | M11: =IF(L11="","",IF(ABS(L11)<=MAX(Inputs!$C$51,Inputs!$C$52*Calc!$J16),"YES","NO"))
A12: =Calc!A17 | B12: =Calc!E17 | C12: =Calc!F17 | D12: =Calc!G17 | E12: =IF(Inputs!$C$48="","",Inputs!$C$48) | F12: =IF(OR(E12="",Calc!$A17=""),"",E12-Calc!$H17) | G12: =IF(F12="","",IF(ABS(F12)<=MAX(Inputs!$C$51,Inputs!$C$52*Calc!$H17),"YES","NO")) | H12: =IF(Inputs!$D$48="","",Inputs!$D$48) | I12: =IF(OR(H12="",Calc!$A17=""),"",H12-Calc!$I17) | J12: =IF(I12="","",IF(ABS(I12)<=MAX(Inputs!$C$51,Inputs!$C$52*Calc!$I17),"YES","NO")) | K12: =IF(Inputs!$E$48="","",Inputs!$E$48) | L12: =IF(OR(K12="",Calc!$A17=""),"",K12-Calc!$J17) | M12: =IF(L12="","",IF(ABS(L12)<=MAX(Inputs!$C$51,Inputs!$C$52*Calc!$J17),"YES","NO"))
A14: All drawing values within tolerance (drawing basis)? | F14: =IF(COUNTIF(G5:G12,"NO")+COUNTIF(J5:J12,"NO")+COUNTIF(M5:M12,"NO")=0,"YES","NO") -> YES
A15: Dev columns compare the drawing with the calculation on the drawing basis (fctk,0.05 = Inputs C8); columns B-D use the basis selected on Inputs (Table 3.1 unless overridden).
A17: Mandrel check (EN 1992-1-1 8.3(1)): 4 phi for phi <= 16 mm, 7 phi above
A18: Bar (mm) | B18: EN mandrel (mm) | C18: Drawing (mm) | D18: Matches?
A19: =Calc!A10 -> 10 | B19: =IF(A19="","",IF(A19<=16,4,7)*A19) -> 40 | C19: =IF(Inputs!$F$41="","",Inputs!$F$41) -> 40 | D19: =IF(OR(A19="",C19=""),"",IF(B19=C19,"YES","NO - CHECK")) -> YES
A20: =Calc!A11 -> 12 | B20: =IF(A20="","",IF(A20<=16,4,7)*A20) -> 48 | C20: =IF(Inputs!$F$42="","",Inputs!$F$42) -> 48 | D20: =IF(OR(A20="",C20=""),"",IF(B20=C20,"YES","NO - CHECK")) -> YES
A21: =Calc!A12 -> 16 | B21: =IF(A21="","",IF(A21<=16,4,7)*A21) -> 64 | C21: =IF(Inputs!$F$43="","",Inputs!$F$43) -> 64 | D21: =IF(OR(A21="",C21=""),"",IF(B21=C21,"YES","NO - CHECK")) -> YES
A22: =Calc!A13 -> 20 | B22: =IF(A22="","",IF(A22<=16,4,7)*A22) -> 140 | C22: =IF(Inputs!$F$44="","",Inputs!$F$44) -> 140 | D22: =IF(OR(A22="",C22=""),"",IF(B22=C22,"YES","NO - CHECK")) -> YES
A23: =Calc!A14 -> 25 | B23: =IF(A23="","",IF(A23<=16,4,7)*A23) -> 175 | C23: =IF(Inputs!$F$45="","",Inputs!$F$45) -> 175 | D23: =IF(OR(A23="",C23=""),"",IF(B23=C23,"YES","NO - CHECK")) -> YES
A24: =Calc!A15 | B24: =IF(A24="","",IF(A24<=16,4,7)*A24) | C24: =IF(Inputs!$F$46="","",Inputs!$F$46) | D24: =IF(OR(A24="",C24=""),"",IF(B24=C24,"YES","NO - CHECK"))
A25: =Calc!A16 | B25: =IF(A25="","",IF(A25<=16,4,7)*A25) | C25: =IF(Inputs!$F$47="","",Inputs!$F$47) | D25: =IF(OR(A25="",C25=""),"",IF(B25=C25,"YES","NO - CHECK"))
A26: =Calc!A17 | B26: =IF(A26="","",IF(A26<=16,4,7)*A26) | C26: =IF(Inputs!$F$48="","",Inputs!$F$48) | D26: =IF(OR(A26="",C26=""),"",IF(B26=C26,"YES","NO - CHECK"))
A28: Mandrel rule values 16 / 4 / 7 are EN 1992-1-1 Table 8.1 constants; they are the only typed numbers outside Inputs and are not design inputs.

Sheet Checks
A1: CHECKS - independent hand calculations vs workbook results
A2: Expected values were worked by hand for the baseline inputs below. If inputs change, checks show N/A (they no longer apply).
B3: Baseline inputs in use? | C3: =IF(AND(Inputs!$C$5="C30/37",Inputs!$C$6=390,Inputs!$C$7="",Inputs!$C$10=1.5,Inputs!$C$11=1.15,Inputs!$C$12=1,Inputs!$C$13=1.5,Inputs!$C$30=10,Inputs!$C$31=12,Inputs!$C$32=16,Inputs!$C$33=20,Inputs!$C$34=25),"YES","NO") -> YES
A4: ID | B4: Test | C4: Expected (hand) | D4: Workbook | E4: Difference | F4: Tolerance | G4: Result | H4: Hand calculation
A5: T1 | B5: fctd, C30/37 | C5: 1.333333 | D5: =Calc!C5 -> 1.3333333 | E5: =D5-C5 -> 3.3333333e-07 | F5: 1e-05 | G5: =IF($C$3<>"YES","N/A - inputs changed",IF(ABS(E5)<=F5,"PASS","FAIL")) -> PASS | H5: 2.0 / 1.5
A6: T2 | B6: fyd, fyk = 390 MPa | C6: 339.13043 | D6: =Calc!C6 -> 339.13043 | E6: =D6-C6 -> -2.1739123e-07 | F6: 0.0001 | G6: =IF($C$3<>"YES","N/A - inputs changed",IF(ABS(E6)<=F6,"PASS","FAIL")) -> PASS | H6: 390 / 1.15
A7: T3 | B7: fbd good bond, phi 12 (MPa) | C7: 3 | D7: =Calc!C11 -> 3 | E7: =D7-C7 -> 0 | F7: 1e-05 | G7: =IF($C$3<>"YES","N/A - inputs changed",IF(ABS(E7)<=F7,"PASS","FAIL")) -> PASS | H7: 2.25 x 1.0 x 1.0 x 1.333333
A8: T4 | B8: fbd poor bond, phi 12 (MPa) | C8: 2.1 | D8: =Calc!D11 -> 2.1 | E8: =D8-C8 -> 0 | F8: 1e-05 | G8: =IF($C$3<>"YES","N/A - inputs changed",IF(ABS(E8)<=F8,"PASS","FAIL")) -> PASS | H8: 0.7 x 3.000
A9: T5 | B9: lb,rqd good, phi 12 (mm) | C9: 339.13043 | D9: =Calc!E11 -> 339.13043 | E9: =D9-C9 -> -2.1739123e-07 | F9: 0.001 | G9: =IF($C$3<>"YES","N/A - inputs changed",IF(ABS(E9)<=F9,"PASS","FAIL")) -> PASS | H9: (12/4) x 339.1304 / 3.000
A10: T6 | B10: lb,rqd poor, phi 12 (mm) | C10: 484.47205 | D10: =Calc!F11 -> 484.47205 | E10: =D10-C10 -> -3.105589e-07 | F10: 0.001 | G10: =IF($C$3<>"YES","N/A - inputs changed",IF(ABS(E10)<=F10,"PASS","FAIL")) -> PASS | H10: (12/4) x 339.1304 / 2.100
A11: T7 | B11: lap l0 good, phi 12 (mm) | C11: 508.69565 | D11: =Calc!G11 -> 508.69565 | E11: =D11-C11 -> 1.7391312e-07 | F11: 0.001 | G11: =IF($C$3<>"YES","N/A - inputs changed",IF(ABS(E11)<=F11,"PASS","FAIL")) -> PASS | H11: 1.5 x 339.1304
A12: T8 | B12: lb,rqd good, phi 25 (mm) | C12: 706.52174 | D12: =Calc!E14 -> 706.52174 | E12: =D12-C12 -> 1.3043484e-07 | F12: 0.001 | G12: =IF($C$3<>"YES","N/A - inputs changed",IF(ABS(E12)<=F12,"PASS","FAIL")) -> PASS | H12: (25/4) x 339.1304 / 3.000

Sheet Log
A1: Date | B1: Change | C1: By
A2: 13-OCT-2026 | B2: Workbook generated by tools/xlsxgen/build_anchorage_workbook.py; recalculated and verified by verify_workbook.py | C2: Claude (generator)
